Workbook
Name _xlchart.v1.3: velo!$C$2:$C$1487
Name _xlchart.v1.0: velo!$C$2:$C$1487
Name _xlchart.v1.1: velo!$G$1
Name _xlchart.v1.5: velo!$G$2:$G$1487
Name _xlchart.v1.4: velo!$G$1
Name _xlchart.v1.2: velo!$G$2:$G$1487

Sheet uzdevumi
A1: Darblapā skola formatēt šūnu apgabala B2:B12 nelietojot tūkstošu atdalītāju.
A2: Darblapā skola šūnā D1 datuma formātā ievadīt datumu pirmdiena, 2015. gada 12. janvāris.
A3: Darblapā skola aizpildīt kolonnu F ar visu 2015. gada sestdienu datumiem.
A4: Darblapu lapa2 pārvietot uz jaunu, tukšu darbgrāmatu, jauno darbgrāmatu saglabāt kā veidni ar nosaukumu zals un aizvērt.
A5: Darblapā perimetrs izveidot līniju diagrammu, izmantojot datus no šūnu apgabala B2:C2;E2;B11:C18;E11:E18.
A6: Darblapā laukums dotajam grafikam pievienot virsrakstu Laukums.
A7: Darblapā vienādsānu šūnas A1 saturu centrēt šūnu apgabalā A1:K1.
A8: Darblapas vienādsānu šūnā K2 veikt teksta aplaušanu.
A9: Darblapas vienādsānu šūnā J3 ievadīt formulu, kas aprēķina, cik leņķu vērtības ir dotas A kolonnā.
A10: Darblapas vienādsānu šūnā K3 ievadīt formulu, kas aprēķina lielāko no A kolonnā dotajiem leņķiem.
A11: Darblapas vienādsānu šūnu apgabalā B3:B70 ievadīt formulu, kas izmantojot datus no kolonnas A, aprēķina vienādsānu trijstūra leņķi pie pamata.
A12: Darblapas vienādsānu šūnu apgabalā C3:C70 ievadīt formulu, kas izmantojot datus no kolonnām D, E un F pēc Hērona formulas aprēķina trijstūra laukumu
... A28: Darblapā pH uzraksti formulu, kas atrod lineāru sakarību (taisnes vienādojumu) starp pielieto nātrija hidroksīdu un pH līmeni.
A30: =28+9+2 -> 39

Sheet skola
A1: 2014./2015. mācību gads | D1: 42016 | F1: 42007
A2: Mācību gada sākums | B2: 41883 | F2: 42014
A3: Mācību gada beigas 1.–8.klases un 10.–11.klašu skolēniem | B3: 42153 | F3: 42021
A4: Mācību gada beigas 9. un 12. klašu skolēniem | B4: 42139 | F4: 42028
A5: Rudens brīvlaika sākums | B5: 41939 | F5: 42035
A6: Rudens brīvlaika beigas | B6: 41943 | F6: 42042
A7: Ziemas brīvlaika sākums | B7: 41995 | F7: 42049
A8: Ziemas brīvlaika beigas | B8: 42006 | F8: 42056
A9: Pavasara brīvlaika sākums 1. -11.klašu skolēniem | B9: 42079 | F9: 42063
A10: Pavasara brīvlaika beigas 1. -11.klašu skolēniem | B10: 42083 | F10: 42070
A11: Pavasara brīvlaika sākums 12. klašu skolēniem | B11: 42086 | F11: 42077
A12: Pavasara brīvlaika beigas 12. klašu skolēniem | B12: 42090 | F12: 42084
F13: 42091
A14: 1 | B14: Ddarblapā skola šūnu apgabalu B2:B12 formatēt, nelietojot tūkstošu atdalītāju. | F14: 42098
C15: 1 punkts | F15: 42105
F16: 42112
F17: 42119
A18: 2 | B18: Ddarblapā skola šūnā D1 datuma formātā ievadīt datumu pirmdiena, 2015. gada 12. janvāris. | F18: 42126
C19: 1 punkts | F19: 42133
F20: 42140
F21: 42147
A22: 3 | B22: Darblapā skola aizpildīt kolonnu F ar visu 2015. gada sestdienu datumiem. | F22: 42154
C23: 1 punkts | F23: 42161
F24: 42168
F25: 42175
F26: 42182
F27: 42189
F28: 42196
F29: 42203
F30: 42210
F31: 42217
F32: 42224
F33: 42231
F34: 42238
F35: 42245
... F52: 42364

Sheet lapa2

Sheet zals

Sheet perimetrs
A1: Taisnleņķa trijstūru perimetri
A2: leņķis1 | B2: leņķis2 | C2: leņķis3 | D2: hipotenūza | E2: perimetrs | P2: 5 | Q2: Darblapā perimetrs izveidot līniju diagrammu, izmantojot datus no šūnu apgabala B2:C2;E2;B11:C18;E11:E18. | V2: 2 punkti
A3: 90 | B3: 10 | C3: =90-B3 -> 80 | D3: 20 | E3: 43.169119
A4: 90 | B4: 20 | C4: =90-B4 -> 70 | D4: 20 | E4: 45.634255
A5: 90 | B5: 30 | C5: =90-B5 -> 60 | D5: 20 | E5: 47.320508
A6: 90 | B6: 40 | C6: =90-B6 -> 50 | D6: 20 | E6: 48.176641
A7: 90 | B7: 50 | C7: =90-B7 -> 40 | D7: 20 | E7: 48.176641
A8: 90 | B8: 60 | C8: =90-B8 -> 30 | D8: 20 | E8: 47.320508
A9: 90 | B9: 70 | C9: =90-B9 -> 20 | D9: 20 | E9: 45.634255
A10: 90 | B10: 80 | C10: =90-B10 -> 10 | D10: 20 | E10: 43.169119
A11: 90 | B11: 10 | C11: =90-B11 -> 80 | D11: 30 | E11: 64.753678
A12: 90 | B12: 20 | C12: =90-B12 -> 70 | D12: 30 | E12: 68.451383
A13: 90 | B13: 30 | C13: =90-B13 -> 60 | D13: 30 | E13: 70.980762
A14: 90 | B14: 40 | C14: =90-B14 -> 50 | D14: 30 | E14: 72.264962
... A26: 90 | B26: 80 | C26: =90-B26 -> 10 | D26: 40 | E26: 86.338237

Sheet laukums
A1: Taisnleņķa trijstūru laukumi
A2: leņķis1 | B2: leņķis2 | C2: leņķis3 | D2: hipotenūza | E2: laukums
A3: 90 | B3: 10 | C3: =90-B3 -> 80 | D3: 20 | E3: 34.202014 | S3: 6 | T3: Darblapā laukums dotajam grafikam pievienot virsrakstu Laukums. | W3: 1 punkts
A4: 90 | B4: 20 | C4: =90-B4 -> 70 | D4: 20 | E4: 64.278761
A5: 90 | B5: 30 | C5: =90-B5 -> 60 | D5: 20 | E5: 86.60254
A6: 90 | B6: 40 | C6: =90-B6 -> 50 | D6: 20 | E6: 98.480775
A7: 90 | B7: 50 | C7: =90-B7 -> 40 | D7: 20 | E7: 98.480775
A8: 90 | B8: 60 | C8: =90-B8 -> 30 | D8: 20 | E8: 86.60254
A9: 90 | B9: 70 | C9: =90-B9 -> 20 | D9: 20 | E9: 64.278761
A10: 90 | B10: 80 | C10: =90-B10 -> 10 | D10: 20 | E10: 34.202014
A11: 90 | B11: 10 | C11: =90-B11 -> 80 | D11: 30 | E11: 76.954532
A12: 90 | B12: 20 | C12: =90-B12 -> 70 | D12: 30 | E12: 144.62721
A13: 90 | B13: 30 | C13: =90-B13 -> 60 | D13: 30 | E13: 194.85572
A14: 90 | B14: 40 | C14: =90-B14 -> 50 | D14: 30 | E14: 221.58174
A15: 90 | B15: 50 | C15: =90-B15 -> 40 | D15: 30 | E15: 221.58174
... A26: 90 | B26: 80 | C26: =90-B26 -> 10 | D26: 40 | E26: 136.80806

Sheet vienādsānu
A1: Aprēķini vienādsānu trijstūrī
A2: alfa (leņķis pret pamatu) | B2: beta (leņķis pie pamata) | C2: S (laukums) | D2: a (pamats) | E2: b (sānu mala) | F2: c (sānu mala) | G2: p (perimetrs) | H2: h (augstums) | I2: tips | J2: skaits | K2: lielākais leņķis
A3: 89 | B3: =(180-A3)/2 -> 45.5 | C3: =SQRT((D3+E3+F3)/2*((D3+E3+F3)/2-D3)*((D3+E3+F3)/2-E3)*((D3+E3+F3)/2-F3)) -> 30.782624 | D3: 11 | E3: 7.8469501 | F3: 7.8469501 | G3: =SUM(D3,F3,E3) -> 26.6939 | H3: =SQRT(E3*E3-D3*D3/4) -> 5.5968407 | I3: =IF(A3>90,"platleņķa","cits") -> cits | J3: =COUNT(A3:A70) -> 68 | K3: =MAX(A3:A70) -> 130
A4: 124 | B4: =(180-A4)/2 -> 28 | C4: =SQRT((D4+E4+F4)/2*((D4+E4+F4)/2-D4)*((D4+E4+F4)/2-E4)*((D4+E4+F4)/2-F4)) -> 16.08421 | D4: 11 | E4: 6.2291353 | F4: 6.2291353 | G4: =SUM(D4,F4,E4) -> 23.458271 | H4: =SQRT(E4*E4-D4*D4/4) -> 2.9244019 | I4: =IF(A4>90,"platleņķa","cits") -> platleņķa | L4: 7 | M4: Darblapā vienādsānu šūnas A1 saturu centrēt šūnu apgabalā A1:K1. | S4: 1 punkts
A5: 39 | B5: =(180-A5)/2 -> 70.5 | C5: =SQRT((D5+E5+F5)/2*((D5+E5+F5)/2-D5)*((D5+E5+F5)/2-E5)*((D5+E5+F5)/2-F5)) -> 101.66086 | D5: 12 | E5: 17.974466 | F5: 17.974466 | G5: =SUM(D5,F5,E5) -> 47.948932 | H5: =SQRT(E5*E5-D5*D5/4) -> 16.943477 | I5: =IF(A5>90,"platleņķa","cits") -> cits
A6: 99 | B6: =(180-A6)/2 -> 40.5 | C6: =SQRT((D6+E6+F6)/2*((D6+E6+F6)/2-D6)*((D6+E6+F6)/2-E6)*((D6+E6+F6)/2-F6)) -> 61.70733 | D6: 17 | E6: 11.178239 | F6: 11.178239 | G6: =SUM(D6,F6,E6) -> 39.356479 | H6: =SQRT(E6*E6-D6*D6/4) -> 7.2596858 | I6: =IF(A6>90,"platleņķa","cits") -> platleņķa
A7: 38 | B7: =(180-A7)/2 -> 71 | C7: =SQRT((D7+E7+F7)/2*((D7+E7+F7)/2-D7)*((D7+E7+F7)/2-E7)*((D7+E7+F7)/2-F7)) -> 490.81164 | D7: 26 | E7: 39.930195 | F7: 39.930195 | G7: =SUM(D7,F7,E7) -> 105.86039 | H7: =SQRT(E7*E7-D7*D7/4) -> 37.754741 | I7: =IF(A7>90,"platleņķa","cits") -> cits | L7: 8 | M7: Darblapas vienādsānu šūnā K2 veikt teksta aplaušanu. | S7: 1 punkts
A8: 100 | B8: =(180-A8)/2 -> 40 | C8: =SQRT((D8+E8+F8)/2*((D8+E8+F8)/2-D8)*((D8+E8+F8)/2-E8)*((D8+E8+F8)/2-F8)) -> 176.4207 | D8: 29 | E8: 18.928406 | F8: 18.928406 | G8: =SUM(D8,F8,E8) -> 66.856811 | H8: =SQRT(E8*E8-D8*D8/4) -> 12.166945 | I8: =IF(A8>90,"platleņķa","cits") -> platleņķa
A9: 54 | B9: =(180-A9)/2 -> 63 | C9: =SQRT((D9+E9+F9)/2*((D9+E9+F9)/2-D9)*((D9+E9+F9)/2-E9)*((D9+E9+F9)/2-F9)) -> 471.51717 | D9: 31 | E9: 34.141684 | F9: 34.141684 | G9: =SUM(D9,F9,E9) -> 99.283367 | H9: =SQRT(E9*E9-D9*D9/4) -> 30.420463 | I9: =IF(A9>90,"platleņķa","cits") -> cits | L9: 9 | M9: Darblapas vienādsānu šūnā J3 ievadīt formulu, kas aprēķina, cik leņķu vērtības ir dotas A kolonnā. | S9: 1 punkts
A10: 26 | B10: =(180-A10)/2 -> 77 | C10: =SQRT((D10+E10+F10)/2*((D10+E10+F10)/2-D10)*((D10+E10+F10)/2-E10)*((D10+E10+F10)/2-F10)) -> 1179.2443 | D10: 33 | E10: 73.349289 | F10: 73.349289 | G10: =SUM(D10,F10,E10) -> 179.69858 | H10: =SQRT(E10*E10-D10*D10/4) -> 71.469352 | I10: =IF(A10>90,"platleņķa","cits") -> cits
A11: 126 | B11: =(180-A11)/2 -> 27 | C11: =SQRT((D11+E11+F11)/2*((D11+E11+F11)/2-D11)*((D11+E11+F11)/2-E11)*((D11+E11+F11)/2-F11)) -> 174.38509 | D11: 37 | E11: 20.763035 | F11: 20.763035 | G11: =SUM(D11,F11,E11) -> 78.526071 | H11: =SQRT(E11*E11-D11*D11/4) -> 9.4262208 | I11: =IF(A11>90,"platleņķa","cits") -> platleņķa
A12: 89 | B12: =(180-A12)/2 -> 45.5 | C12: =SQRT((D12+E12+F12)/2*((D12+E12+F12)/2-D12)*((D12+E12+F12)/2-E12)*((D12+E12+F12)/2-F12)) -> 407.04296 | D12: 40 | E12: 28.534364 | F12: 28.534364 | G12: =SUM(D12,F12,E12) -> 97.068728 | H12: =SQRT(E12*E12-D12*D12/4) -> 20.352148 | I12: =IF(A12>90,"platleņķa","cits") -> cits
A13: 37 | B13: =(180-A13)/2 -> 71.5 | C13: =SQRT((D13+E13+F13)/2*((D13+E13+F13)/2-D13)*((D13+E13+F13)/2-E13)*((D13+E13+F13)/2-F13)) -> 1255.9949 | D13: 41 | E13: 64.606679 | F13: 64.606679 | G13: =SUM(D13,F13,E13) -> 170.21336 | H13: =SQRT(E13*E13-D13*D13/4) -> 61.268042 | I13: =IF(A13>90,"platleņķa","cits") -> cits | L13: 10 | M13: Darblapas vienādsānu šūnā K3 ievadīt formulu, kas aprēķina lielāko no A kolonnā dotajiem leņķiem. | S13: 1 punkts
A14: 38 | B14: =(180-A14)/2 -> 71 | C14: =SQRT((D14+E14+F14)/2*((D14+E14+F14)/2-D14)*((D14+E14+F14)/2-E14)*((D14+E14+F14)/2-F14)) -> 1220.4946 | D14: 41 | E14: 62.966846 | F14: 62.966846 | G14: =SUM(D14,F14,E14) -> 166.93369 | H14: =SQRT(E14*E14-D14*D14/4) -> 59.536323 | I14: =IF(A14>90,"platleņķa","cits") -> cits
A15: 14 | B15: =(180-A15)/2 -> 83 | C15: =SQRT((D15+E15+F15)/2*((D15+E15+F15)/2-D15)*((D15+E15+F15)/2-E15)*((D15+E15+F15)/2-F15)) -> 3764.7241 | D15: 43 | E15: 176.41844 | F15: 176.41844 | G15: =SUM(D15,F15,E15) -> 395.83689 | H15: =SQRT(E15*E15-D15*D15/4) -> 175.10345 | I15: =IF(A15>90,"platleņķa","cits") -> cits
A16: 75 | B16: =(180-A16)/2 -> 52.5 | C16: =SQRT((D16+E16+F16)/2*((D16+E16+F16)/2-D16)*((D16+E16+F16)/2-E16)*((D16+E16+F16)/2-F16)) -> 602.41593 | D16: 43 | E16: 35.317612 | F16: 35.317612 | G16: =SUM(D16,F16,E16) -> 113.63522 | H16: =SQRT(E16*E16-D16*D16/4) -> 28.019346 | I16: =IF(A16>90,"platleņķa","cits") -> cits
A17: 67 | B17: =(180-A17)/2 -> 56.5 | C17: =SQRT((D17+E17+F17)/2*((D17+E17+F17)/2-D17)*((D17+E17+F17)/2-E17)*((D17+E17+F17)/2-F17)) -> 698.38357 | D17: 43 | E17: 38.953722 | F17: 38.953722 | G17: =SUM(D17,F17,E17) -> 120.90744 | H17: =SQRT(E17*E17-D17*D17/4) -> 32.482957 | I17: =IF(A17>90,"platleņķa","cits") -> cits | L17: 11 | M17: Darblapas vienādsānu šūnu apgabalā B3:B70 ievadīt formulu, kas izmantojot datus no kolonnas A, aprēķina vienādsānu trijstūra leņķi pie pamata. | S17: 1 punkts
A18: 114 | B18: =(180-A18)/2 -> 33 | C18: =SQRT((D18+E18+F18)/2*((D18+E18+F18)/2-D18)*((D18+E18+F18)/2-E18)*((D18+E18+F18)/2-F18)) -> 328.76259 | D18: 45 | E18: 26.828174 | F18: 26.828174 | G18: =SUM(D18,F18,E18) -> 98.656348 | H18: =SQRT(E18*E18-D18*D18/4) -> 14.611671 | I18: =IF(A18>90,"platleņķa","cits") -> platleņķa
A19: 124 | B19: =(180-A19)/2 -> 28 | C19: =SQRT((D19+E19+F19)/2*((D19+E19+F19)/2-D19)*((D19+E19+F19)/2-E19)*((D19+E19+F19)/2-F19)) -> 269.1779 | D19: 45 | E19: 25.482826 | F19: 25.482826 | G19: =SUM(D19,F19,E19) -> 95.965652 | H19: =SQRT(E19*E19-D19*D19/4) -> 11.963462 | I19: =IF(A19>90,"platleņķa","cits") -> platleņķa
A20: 57 | B20: =(180-A20)/2 -> 61.5 | C20: =SQRT((D20+E20+F20)/2*((D20+E20+F20)/2-D20)*((D20+E20+F20)/2-E20)*((D20+E20+F20)/2-F20)) -> 974.2968 | D20: 46 | E20: 48.201986 | F20: 48.201986 | G20: =SUM(D20,F20,E20) -> 142.40397 | H20: =SQRT(E20*E20-D20*D20/4) -> 42.36073 | I20: =IF(A20>90,"platleņķa","cits") -> cits
A21: 90 | B21: =(180-A21)/2 -> 45 | C21: =SQRT((D21+E21+F21)/2*((D21+E21+F21)/2-D21)*((D21+E21+F21)/2-E21)*((D21+E21+F21)/2-F21)) -> 552.25 | D21: 47 | E21: 33.234019 | F21: 33.234019 | G21: =SUM(D21,F21,E21) -> 113.46804 | H21: =SQRT(E21*E21-D21*D21/4) -> 23.5 | I21: =IF(A21>90,"platleņķa","cits") -> cits | L21: 12 | M21: Darblapas vienādsānu šūnu apgabalā C3:C70 ievadīt formulu, kas izmantojot datus no kolonnām D, E un F pēc Hērona formulas aprēķina trijstūra laukumu | S21: 2 punkti
A22: 45 | B22: =(180-A22)/2 -> 67.5 | C22: =SQRT((D22+E22+F22)/2*((D22+E22+F22)/2-D22)*((D22+E22+F22)/2-E22)*((D22+E22+F22)/2-F22)) -> 1333.2494 | D22: 47 | E22: 61.408459 | F22: 61.408459 | G22: =SUM(D22,F22,E22) -> 169.81692 | H22: =SQRT(E22*E22-D22*D22/4) -> 56.734019 | I22: =IF(A22>90,"platleņķa","cits") -> cits
A23: 85 | B23: =(180-A23)/2 -> 47.5 | C23: =SQRT((D23+E23+F23)/2*((D23+E23+F23)/2-D23)*((D23+E23+F23)/2-E23)*((D23+E23+F23)/2-F23)) -> 917.79045 | D23: 58 | E23: 42.92543 | F23: 42.92543 | G23: =SUM(D23,F23,E23) -> 143.85086 | H23: =SQRT(E23*E23-D23*D23/4) -> 31.647947 | I23: =IF(A23>90,"platleņķa","cits") -> cits
A24: 42 | B24: =(180-A24)/2 -> 69 | C24: =SQRT((D24+E24+F24)/2*((D24+E24+F24)/2-D24)*((D24+E24+F24)/2-E24)*((D24+E24+F24)/2-F24)) -> 2190.8799 | D24: 58 | E24: 80.922415 | F24: 80.922415 | G24: =SUM(D24,F24,E24) -> 219.84483 | H24: =SQRT(E24*E24-D24*D24/4) -> 75.547583 | I24: =IF(A24>90,"platleņķa","cits") -> cits
A25: 92 | B25: =(180-A25)/2 -> 44 | C25: =SQRT((D25+E25+F25)/2*((D25+E25+F25)/2-D25)*((D25+E25+F25)/2-E25)*((D25+E25+F25)/2-F25)) -> 869.1199 | D25: 60 | E25: 41.704908 | F25: 41.704908 | G25: =SUM(D25,F25,E25) -> 143.40982 | H25: =SQRT(E25*E25-D25*D25/4) -> 28.970663 | I25: =IF(A25>90,"platleņķa","cits") -> platleņķa | L25: 13 | M25: Darblapas vienādsānu šūnu apgabalā H3:H70 ievadīt formulu, kas izmantojot datus no kolonnām D un E, aprēķina vienādsānu trijstūra augstumu pret pamatu. | S25: 1 punkts
A26: 103 | B26: =(180-A26)/2 -> 38.5 | C26: =SQRT((D26+E26+F26)/2*((D26+E26+F26)/2-D26)*((D26+E26+F26)/2-E26)*((D26+E26+F26)/2-F26)) -> 739.95426 | D26: 61 | E26: 38.972249 | F26: 38.972249 | G26: =SUM(D26,F26,E26) -> 138.9445 | H26: =SQRT(E26*E26-D26*D26/4) -> 24.260795 | I26: =IF(A26>90,"platleņķa","cits") -> platleņķa
A27: 62 | B27: =(180-A27)/2 -> 59 | C27: =SQRT((D27+E27+F27)/2*((D27+E27+F27)/2-D27)*((D27+E27+F27)/2-E27)*((D27+E27+F27)/2-F27)) -> 1599.3726 | D27: 62 | E27: 60.189725 | F27: 60.189725 | G27: =SUM(D27,F27,E27) -> 182.37945 | H27: =SQRT(E27*E27-D27*D27/4) -> 51.592664 | I27: =IF(A27>90,"platleņķa","cits") -> cits
A28: 109 | B28: =(180-A28)/2 -> 35.5 | C28: =SQRT((D28+E28+F28)/2*((D28+E28+F28)/2-D28)*((D28+E28+F28)/2-E28)*((D28+E28+F28)/2-F28)) -> 753.4158 | D28: 65 | E28: 39.920625 | F28: 39.920625 | G28: =SUM(D28,F28,E28) -> 144.84125 | H28: =SQRT(E28*E28-D28*D28/4) -> 23.182025 | I28: =IF(A28>90,"platleņķa","cits") -> platleņķa
A29: 96 | B29: =(180-A29)/2 -> 42 | C29: =SQRT((D29+E29+F29)/2*((D29+E29+F29)/2-D29)*((D29+E29+F29)/2-E29)*((D29+E29+F29)/2-F29)) -> 980.54 | D29: 66 | E29: 44.40588 | F29: 44.40588 | G29: =SUM(D29,F29,E29) -> 154.81176 | H29: =SQRT(E29*E29-D29*D29/4) -> 29.713333 | I29: =IF(A29>90,"platleņķa","cits") -> platleņķa | L29: 14 | M29: Darblapas vienādsānu šūnu apgabalā G3:G70 dota formula, kas kļūdaini aprēķina vienādsānu trijstūra perimetru pēc sakarības p=a+b+c. Izlabot kļūdu, nemainot izmantoto funkciju. | S29: 1 punkts
A30: 118 | B30: =(180-A30)/2 -> 31 | C30: =SQRT((D30+E30+F30)/2*((D30+E30+F30)/2-D30)*((D30+E30+F30)/2-E30)*((D30+E30+F30)/2-F30)) -> 674.31583 | D30: 67 | E30: 39.082219 | F30: 39.082219 | G30: =SUM(D30,F30,E30) -> 145.16444 | H30: =SQRT(E30*E30-D30*D30/4) -> 20.128831 | I30: =IF(A30>90,"platleņķa","cits") -> platleņķa
A31: 96 | B31: =(180-A31)/2 -> 42 | C31: =SQRT((D31+E31+F31)/2*((D31+E31+F31)/2-D31)*((D31+E31+F31)/2-E31)*((D31+E31+F31)/2-F31)) -> 2117.9754 | D31: 97 | E31: 65.263187 | F31: 65.263187 | G31: =SUM(D31,F31,E31) -> 227.52637 | H31: =SQRT(E31*E31-D31*D31/4) -> 43.669596 | I31: =IF(A31>90,"platleņķa","cits") -> platleņķa
A32: 14 | B32: =(180-A32)/2 -> 83 | C32: =SQRT((D32+E32+F32)/2*((D32+E32+F32)/2-D32)*((D32+E32+F32)/2-E32)*((D32+E32+F32)/2-F32)) -> 9693.8083 | D32: 69 | E32: 283.09006 | F32: 283.09006 | G32: =SUM(D32,F32,E32) -> 635.18012 | H32: =SQRT(E32*E32-D32*D32/4) -> 280.97995 | I32: =IF(A32>90,"platleņķa","cits") -> cits
A33: 102 | B33: =(180-A33)/2 -> 39 | C33: =SQRT((D33+E33+F33)/2*((D33+E33+F33)/2-D33)*((D33+E33+F33)/2-E33)*((D33+E33+F33)/2-F33)) -> 1020.5303 | D33: 71 | E33: 45.679965 | F33: 45.679965 | G33: =SUM(D33,F33,E33) -> 162.35993 | H33: =SQRT(E33*E33-D33*D33/4) -> 28.747333 | I33: =IF(A33>90,"platleņķa","cits") -> platleņķa
A34: 102 | B34: =(180-A34)/2 -> 39 | C34: =SQRT((D34+E34+F34)/2*((D34+E34+F34)/2-D34)*((D34+E34+F34)/2-E34)*((D34+E34+F34)/2-F34)) -> 1020.5303 | D34: 71 | E34: 45.679965 | F34: 45.679965 | G34: =SUM(D34,F34,E34) -> 162.35993 | H34: =SQRT(E34*E34-D34*D34/4) -> 28.747333 | I34: =IF(A34>90,"platleņķa","cits") -> platleņķa | L34: 15 | M34: Darblapas vienādsānu šūnu apgabalā I3:I70 ievadīt formulu, kas aprēķina vienādsānu trijstūra tipu. Formulai jāparāda teksts „platleņķa”, ja A kolonnā dotais leņķis ir lielāks par 90, vai arī teksts „cits” pretējā gadījumā. | S34: 1 punkts
A35: 62 | B35: =(180-A35)/2 -> 59 | C35: =SQRT((D35+E35+F35)/2*((D35+E35+F35)/2-D35)*((D35+E35+F35)/2-E35)*((D35+E35+F35)/2-F35)) -> 2278.3986 | D35: 74 | E35: 71.839349 | F35: 71.839349 | G35: =SUM(D35,F35,E35) -> 217.6787 | H35: =SQRT(E35*E35-D35*D35/4) -> 61.578341 | I35: =IF(A35>90,"platleņķa","cits") -> cits
A36: 50 | B36: =(180-A36)/2 -> 65 | C36: =SQRT((D36+E36+F36)/2*((D36+E36+F36)/2-D36)*((D36+E36+F36)/2-E36)*((D36+E36+F36)/2-F36)) -> 2935.83 | D36: 74 | E36: 87.549459 | F36: 87.549459 | G36: =SUM(D36,F36,E36) -> 249.09892 | H36: =SQRT(E36*E36-D36*D36/4) -> 79.346756 | I36: =IF(A36>90,"platleņķa","cits") -> cits
A37: 128 | B37: =(180-A37)/2 -> 26 | C37: =SQRT((D37+E37+F37)/2*((D37+E37+F37)/2-D37)*((D37+E37+F37)/2-E37)*((D37+E37+F37)/2-F37)) -> 722.94163 | D37: 77 | E37: 42.835175 | F37: 42.835175 | G37: =SUM(D37,F37,E37) -> 162.67035 | H37: =SQRT(E37*E37-D37*D37/4) -> 18.777705 | I37: =IF(A37>90,"platleņķa","cits") -> platleņķa
A38: 16 | B38: =(180-A38)/2 -> 82 | C38: =SQRT((D38+E38+F38)/2*((D38+E38+F38)/2-D38)*((D38+E38+F38)/2-E38)*((D38+E38+F38)/2-F38)) -> 10822.477 | D38: 78 | E38: 280.22656 | F38: 280.22656 | G38: =SUM(D38,F38,E38) -> 638.45313 | H38: =SQRT(E38*E38-D38*D38/4) -> 277.49942 | I38: =IF(A38>90,"platleņķa","cits") -> cits
A39: 11 | B39: =(180-A39)/2 -> 84.5 | C39: =SQRT((D39+E39+F39)/2*((D39+E39+F39)/2-D39)*((D39+E39+F39)/2-E39)*((D39+E39+F39)/2-F39)) -> 15796.189 | D39: 78 | E39: 406.90379 | F39: 406.90379 | G39: =SUM(D39,F39,E39) -> 891.80758 | H39: =SQRT(E39*E39-D39*D39/4) -> 405.03049 | I39: =IF(A39>90,"platleņķa","cits") -> cits
A40: 60 | B40: =(180-A40)/2 -> 60 | C40: =SQRT((D40+E40+F40)/2*((D40+E40+F40)/2-D40)*((D40+E40+F40)/2-E40)*((D40+E40+F40)/2-F40)) -> 2911.5774 | D40: 82 | E40: 82 | F40: 82 | G40: =SUM(D40,F40,E40) -> 246 | H40: =SQRT(E40*E40-D40*D40/4) -> 71.014083 | I40: =IF(A40>90,"platleņķa","cits") -> cits
...

Sheet taisnleņķa
A1: Aprēķināt visu iespējamo taisnleņķa trijstūru laukumus
B2: hipotenūza
A3: leņķis grādos | B3: 10 | C3: 12 | D3: 14 | E3: 16 | F3: 18 | G3: 20 | J3: 16 | K3: Darblapas taisnleņķa šūnu apgabalā B4:G9 ievadīt formulu, kas izmantojot dotos datus, aprēķina visu taisnleņķa trijstūru laukumus. | P3: 3 punkti
A4: 20 | B4: =($B$3*SIN(RADIANS(A4))*$B$3*COS(RADIANS(A4)))/2 -> 16.06969 | C4: =($C$3*SIN(RADIANS(A4))*C$3*COS(RADIANS(A4)))/2 -> 23.140354 | D4: =($D$3*SIN(RADIANS(A4))*$D$3*COS(RADIANS(A4)))/2 -> 31.496593 | E4: =($E$3*SIN(RADIANS(A4))*$E$3*COS(RADIANS(A4)))/2 -> 41.138407 | F4: =($F$3*SIN(RADIANS(A4))*$F$3*COS(RADIANS(A4)))/2 -> 52.065796 | G4: =($G$3*SIN(RADIANS(A4))*$G$3*COS(RADIANS(A4)))/2 -> 64.278761
A5: 30 | B5: =($B$3*SIN(RADIANS(A5))*$B$3*COS(RADIANS(A5)))/2 -> 21.650635 | C5: =($C$3*SIN(RADIANS(A5))*C$3*COS(RADIANS(A5)))/2 -> 31.176915 | D5: =($D$3*SIN(RADIANS(A5))*$D$3*COS(RADIANS(A5)))/2 -> 42.435245 | E5: =($E$3*SIN(RADIANS(A5))*$E$3*COS(RADIANS(A5)))/2 -> 55.425626 | F5: =($F$3*SIN(RADIANS(A5))*$F$3*COS(RADIANS(A5)))/2 -> 70.148058 | G5: =($G$3*SIN(RADIANS(A5))*$G$3*COS(RADIANS(A5)))/2 -> 86.60254
A6: 40 | B6: =($B$3*SIN(RADIANS(A6))*$B$3*COS(RADIANS(A6)))/2 -> 24.620194 | C6: =($C$3*SIN(RADIANS(A6))*C$3*COS(RADIANS(A6)))/2 -> 35.453079 | D6: =($D$3*SIN(RADIANS(A6))*$D$3*COS(RADIANS(A6)))/2 -> 48.25558 | E6: =($E$3*SIN(RADIANS(A6))*$E$3*COS(RADIANS(A6)))/2 -> 63.027696 | F6: =($F$3*SIN(RADIANS(A6))*$F$3*COS(RADIANS(A6)))/2 -> 79.769428 | G6: =($G$3*SIN(RADIANS(A6))*$G$3*COS(RADIANS(A6)))/2 -> 98.480775
A7: 50 | B7: =($B$3*SIN(RADIANS(A7))*$B$3*COS(RADIANS(A7)))/2 -> 24.620194 | C7: =($C$3*SIN(RADIANS(A7))*C$3*COS(RADIANS(A7)))/2 -> 35.453079 | D7: =($D$3*SIN(RADIANS(A7))*$D$3*COS(RADIANS(A7)))/2 -> 48.25558 | E7: =($E$3*SIN(RADIANS(A7))*$E$3*COS(RADIANS(A7)))/2 -> 63.027696 | F7: =($F$3*SIN(RADIANS(A7))*$F$3*COS(RADIANS(A7)))/2 -> 79.769428 | G7: =($G$3*SIN(RADIANS(A7))*$G$3*COS(RADIANS(A7)))/2 -> 98.480775
A8: 60 | B8: =($B$3*SIN(RADIANS(A8))*$B$3*COS(RADIANS(A8)))/2 -> 21.650635 | C8: =($C$3*SIN(RADIANS(A8))*C$3*COS(RADIANS(A8)))/2 -> 31.176915 | D8: =($D$3*SIN(RADIANS(A8))*$D$3*COS(RADIANS(A8)))/2 -> 42.435245 | E8: =($E$3*SIN(RADIANS(A8))*$E$3*COS(RADIANS(A8)))/2 -> 55.425626 | F8: =($F$3*SIN(RADIANS(A8))*$F$3*COS(RADIANS(A8)))/2 -> 70.148058 | G8: =($G$3*SIN(RADIANS(A8))*$G$3*COS(RADIANS(A8)))/2 -> 86.60254
A9: 70 | B9: =($B$3*SIN(RADIANS(A9))*$B$3*COS(RADIANS(A9)))/2 -> 16.06969 | C9: =($C$3*SIN(RADIANS(A9))*C$3*COS(RADIANS(A9)))/2 -> 23.140354 | D9: =($D$3*SIN(RADIANS(A9))*$D$3*COS(RADIANS(A9)))/2 -> 31.496593 | E9: =($E$3*SIN(RADIANS(A9))*$E$3*COS(RADIANS(A9)))/2 -> 41.138407 | F9: =($F$3*SIN(RADIANS(A9))*$F$3*COS(RADIANS(A9)))/2 -> 52.065796 | G9: =($G$3*SIN(RADIANS(A9))*$G$3*COS(RADIANS(A9)))/2 -> 64.278761

Sheet dati1
A1: Aprēķini trijstūrī
A2: Trijstūra virsotņu koordinātes
A3: x1 | B3: y1 | C3: x2 | D3: y2 | E3: x3 | F3: y3 | G3: leņķis1 | H3: leņķis2 | I3: leņķis3 | J3: laukums | K3: mala1 | L3: mala2 | M3: mala3
A4: 81 | B4: -52 | C4: 74 | D4: 27 | E4: 75 | F4: 14 | G4: 179.20428 | H4: 0.6649115 | I4: 0.13081205 | J4: 12 | K4: 79.30952 | L4: 13.038405 | M4: 66.272166 | N4: =IF(OR(G4>90,H4>90,I4>90),"nav šaurleņķa","ir šaurleņķa") -> nav šaurleņķa | O4: 20 | P4: Darblapā dati1 sakārtot šūnu apgabala A4:M71 datus augošā secībā pēc laukuma vērtības. | T4: 1 punkts
A5: 53 | B5: -2 | C5: 53 | D5: -1 | E5: 6 | F5: -45 | G5: 0.65661637 | H5: 46.888188 | I5: 132.4552 | J5: 47 | K5: 1 | L5: 64.381674 | M5: 63.702433 | N5: =IF(OR(G5>90,H5>90,I5>90),"nav šaurleņķa","ir šaurleņķa") -> nav šaurleņķa
A6: 74 | B6: -96 | C6: 38 | D6: 10 | E6: 19 | F6: 64 | G6: 0.41410787 | H6: 179.37413 | I6: 0.21175746 | J6: 70 | K6: 111.94642 | L6: 57.245087 | M6: 169.18924 | N6: =IF(OR(G6>90,H6>90,I6>90),"nav šaurleņķa","ir šaurleņķa") -> nav šaurleņķa
A7: 74 | B7: 40 | C7: 73 | D7: 54 | E7: 65 | F7: -7 | G7: 3.3687463 | H7: 11.557176 | I7: 165.07408 | J7: 173 | K7: 14.035669 | L7: 61.522354 | M7: 47.853944 | N7: =IF(OR(G7>90,H7>90,I7>90),"nav šaurleņķa","ir šaurleņķa") -> nav šaurleņķa
A8: 77 | B8: 75 | C8: -65 | D8: -63 | E8: -81 | F8: -80 | G8: 2.2848486 | H8: 177.44584 | I8: 0.26931145 | J8: 206 | K8: 198.0101 | L8: 23.345235 | M8: 221.33459 | N8: =IF(OR(G8>90,H8>90,I8>90),"nav šaurleņķa","ir šaurleņķa") -> nav šaurleņķa | O8: 21 | P8: Darblapā dati1 šūnu apgabalā N4:N71 ievadīt formulu, kas pēc G, H un I kolonnās dotajām leņķu vērtībām nosaka atbilstošā trijstūra tipu. Formulai jāparāda teksts ir šaurleņķa, ja neviens no leņķiem nav lielāks par 90o, vai arī teksts nav šaurleņķa pretējā gadījumā. | T8: 2 punkti
A9: 53 | B9: 55 | C9: 55 | D9: 12 | E9: 50 | F9: 12 | G9: 86.009087 | H9: 87.336999 | I9: 6.6539139 | J9: 215 | K9: 43.046487 | L9: 5 | M9: 43.104524 | N9: =IF(OR(G9>90,H9>90,I9>90),"nav šaurleņķa","ir šaurleņķa") -> ir šaurleņķa
A10: 88 | B10: -95 | C10: 88 | D10: -88 | E10: 45 | F10: -57 | G10: 5.678732 | H10: 125.78897 | I10: 48.532295 | J10: 301 | K10: 7 | L10: 53.009433 | M10: 57.384667 | N10: =IF(OR(G10>90,H10>90,I10>90),"nav šaurleņķa","ir šaurleņķa") -> nav šaurleņķa
A11: -84 | B11: -61 | C11: -10 | D11: -13 | E11: -28 | F11: -29 | G11: 168.11134 | H11: 8.6641354 | I11: 3.2245226 | J11: 320 | K11: 88.204308 | L11: 24.083189 | M11: 64.498062 | N11: =IF(OR(G11>90,H11>90,I11>90),"nav šaurleņķa","ir šaurleņķa") -> nav šaurleņķa
A12: 82 | B12: -68 | C12: 40 | D12: 0 | E12: -26 | F12: 99 | G12: 0.79905251 | H12: 178.01136 | I12: 1.1895853 | J12: 330 | K12: 79.924965 | L12: 118.98319 | M12: 198.87936 | N12: =IF(OR(G12>90,H12>90,I12>90),"nav šaurleņķa","ir šaurleņķa") -> nav šaurleņķa
A13: -58 | B13: -88 | C13: -30 | D13: -16 | E13: -17 | F13: 30 | G13: 3.3794198 | H13: 174.53025 | I13: 2.0903324 | J13: 352 | K13: 77.252832 | L13: 47.801674 | M13: 124.91997 | N13: =IF(OR(G13>90,H13>90,I13>90),"nav šaurleņķa","ir šaurleņķa") -> nav šaurleņķa
A14: -51 | B14: -71 | C14: 88 | D14: 54 | E14: 22 | F14: -8 | G14: 177.58455 | H14: 1.2456585 | I14: 1.1697879 | J14: 368 | K14: 186.93849 | L14: 90.553851 | M14: 96.426138 | N14: =IF(OR(G14>90,H14>90,I14>90),"nav šaurleņķa","ir šaurleņķa") -> nav šaurleņķa
A15: -5 | B15: -73 | C15: -14 | D15: 12 | E15: -25 | F15: 58 | G15: 4.7681966 | H15: 172.59548 | I15: 2.6363263 | J15: 521 | K15: 85.475143 | L15: 47.296934 | M15: 132.51792 | N15: =IF(OR(G15>90,H15>90,I15>90),"nav šaurleņķa","ir šaurleņķa") -> nav šaurleņķa
A16: 65 | B16: -13 | C16: 74 | D16: 23 | E16: 72 | F16: 86 | G16: 5.8627885 | H16: 164.14545 | I16: 9.9917579 | J16: 639 | K16: 37.107951 | L16: 63.031738 | M16: 99.247166 | N16: =IF(OR(G16>90,H16>90,I16>90),"nav šaurleņķa","ir šaurleņķa") -> nav šaurleņķa
A17: -20 | B17: 22 | C17: 51 | D17: -7 | E17: 45 | F17: 5 | G17: 131.2218 | H17: 41.217355 | I17: 7.5608432 | J17: 678 | K17: 76.694198 | L17: 13.416408 | M17: 67.186308 | N17: =IF(OR(G17>90,H17>90,I17>90),"nav šaurleņķa","ir šaurleņķa") -> nav šaurleņķa
A18: -97 | B18: 76 | C18: 84 | D18: -55 | E18: 45 | F18: -32 | G18: 173.27442 | H18: 5.3656932 | I18: 1.3598903 | J18: 946 | K18: 223.43232 | L18: 45.276926 | M18: 178.40404 | N18: =IF(OR(G18>90,H18>90,I18>90),"nav šaurleņķa","ir šaurleņķa") -> nav šaurleņķa
A19: 25 | B19: -15 | C19: 21 | D19: -24 | E19: -91 | F19: 1 | G19: 4.7296492 | H19: 101.37953 | I19: 73.890824 | J19: 1108 | K19: 9.8488578 | L19: 114.75626 | M19: 117.09825 | N19: =IF(OR(G19>90,H19>90,I19>90),"nav šaurleņķa","ir šaurleņķa") -> nav šaurleņķa
A20: -6 | B20: -40 | C20: -31 | D20: 50 | E20: -54 | F20: 86 | G20: 11.719599 | H20: 162.95005 | I20: 5.330347 | J20: 1170 | K20: 93.407708 | L20: 42.720019 | M20: 134.83323 | N20: =IF(OR(G20>90,H20>90,I20>90),"nav šaurleņķa","ir šaurleņķa") -> nav šaurleņķa
... A71: 24 | B71: 86 | C71: -51 | D71: -37 | E71: 95 | F71: -84 | G71: 49.487997 | H71: 76.471286 | I71: 54.040716 | J71: 21483 | K71: 144.06249 | L71: 153.37862 | M71: 184.23083 | N71: =IF(OR(G71>90,H71>90,I71>90),"nav šaurleņķa","ir šaurleņķa") -> ir šaurleņķa

Sheet dati2
A1: Aprēķini trijstūrī
A2: Trijstūra virsotņu koordinātes | N2: =AVERAGE(N4:N71) -> 326.47189
A3: x1 | B3: y1 | C3: x2 | D3: y2 | E3: x3 | F3: y3 | G3: leņķis1 | H3: leņķis2 | I3: leņķis3 | J3: laukums | K3: mala1 | L3: mala2 | M3: mala3 | N3: perimetrs
A4: -35 | B4: 97 | C4: 79 | D4: -4 | E4: -43 | F4: -27 | G4: 75.632258 | H4: 52.216172 | I4: 52.151569 | J4: 14944 | K4: 152.30561 | L4: 124.1491 | M4: 124.2578 | N4: 400.71251 | P4: 17 | Q4: Darblapai dati2 iesaldēt pirmās trīs rindas. | U4: 1 punkts
A5: -88 | B5: -69 | C5: 87 | D5: 17 | E5: -45 | F5: 58 | G5: 91.450099 | H5: 43.425931 | I5: 45.12397 | J5: 18527 | K5: 194.98974 | L5: 138.22084 | M5: 134.08206 | N5: 467.29265
A6: 43 | B6: -59 | C6: -93 | D6: -66 | E6: 8 | F6: 40 | G6: 63.086615 | H6: 43.43724 | I6: 73.476145 | J6: 13709 | K6: 136.18003 | L6: 146.4138 | M6: 105.00476 | N6: 387.59859 | P6: 18 | Q6: Darblapā dati2 formatēt šūnu apgabala G4:N71 datus kā decimālskaitļus ar trīs cipariem aiz komata. | U6: 1 punkts
A7: 97 | B7: -51 | C7: 72 | D7: -18 | E7: 10 | F7: -76 | G7: 27.058508 | H7: 84.055839 | I7: 68.885653 | J7: 3496 | K7: 41.400483 | L7: 84.899941 | M7: 90.520716 | N7: 216.82114
A8: -41 | B8: -26 | C8: -82 | D8: 62 | E8: 97 | F8: -42 | G8: 23.543367 | H8: 34.861933 | I8: 121.5947 | J8: 11488 | K8: 97.082439 | L8: 207.01932 | M8: 138.92444 | N8: 443.0262
A9: 46 | B9: -56 | C9: 5 | D9: 35 | E9: -1 | F9: 3 | G9: 130.83916 | H9: 34.873575 | I9: 14.287264 | J9: 1858 | K9: 99.809819 | L9: 32.557641 | M9: 75.432089 | N9: 207.79955
A10: 41 | B10: -70 | C10: 27 | D10: 76 | E10: -71 | F10: -81 | G10: 52.418158 | H10: 37.449936 | I10: 90.131906 | J10: 16506 | K10: 146.6697 | L10: 185.07566 | M10: 112.53888 | N10: 444.28424 | P10: 19 | Q10: Darblapā dati2 šūnā N2 ievadīt formulu, kas aprēķina vidējo no dotajiem trijstūru perimetriem. | U10: 1 punkts
A11: -28 | B11: -91 | C11: 73 | D11: 10 | E11: 21 | F11: 77 | G11: 54.075937 | H11: 97.184267 | I11: 28.739795 | J11: 12019 | K11: 142.83557 | L11: 84.811556 | M11: 175 | N11: 402.64713
A12: -14 | B12: -70 | C12: -25 | D12: 97 | E12: 73 | F12: 94 | G12: 63.808 | H12: 84.478065 | I12: 31.713935 | J12: 16333 | K12: 167.36188 | L12: 98.045908 | M12: 185.64752 | N12: 451.05531
A13: -59 | B13: 81 | C13: 2 | D13: -53 | E13: -16 | F13: -11 | G13: 178.14761 | H13: 1.277571 | I13: 0.57481631 | J13: 150 | K13: 147.23111 | L13: 45.694639 | M13: 101.55294 | N13: 294.47869
A14: -96 | B14: 47 | C14: 37 | D14: -44 | E14: 35 | F14: 71 | G14: 80.614543 | H14: 54.623307 | I14: 44.76215 | J14: 15113 | K14: 161.1521 | L14: 115.01739 | M14: 133.18033 | N14: 409.34982
A15: -7 | B15: -30 | C15: -72 | D15: -3 | E15: -75 | F15: -80 | G15: 51.441999 | H15: 69.673928 | I15: 58.884073 | J15: 5086 | K15: 70.384657 | L15: 77.058419 | M15: 84.403791 | N15: 231.84687
A16: 90 | B16: -17 | C16: 75 | D16: 81 | E16: 56 | F16: -22 | G16: 71.182481 | H16: 19.153857 | I16: 89.663662 | J16: 3407 | K16: 99.141313 | L16: 104.73777 | M16: 34.365681 | N16: 238.24476
A17: 59 | B17: -26 | C17: -82 | D17: -99 | E17: -13 | F17: -36 | G17: 145.50972 | H17: 15.025457 | I17: 19.464818 | J17: 3846 | K17: 158.77657 | L17: 93.434469 | M17: 72.691127 | N17: 324.90217
A18: -32 | B18: -6 | C18: 50 | D18: 35 | E18: 69 | F18: -82 | G18: 43.815522 | H18: 72.658871 | I18: 63.525607 | J18: 10373 | K18: 91.678787 | L18: 118.5327 | M18: 126.40016 | N18: 336.61164
A19: 88 | B19: 7 | C19: 6 | D19: 56 | E19: -58 | F19: 49 | G19: 22.290919 | H19: 142.89719 | I19: 14.811887 | J19: 3710 | K19: 95.524866 | L19: 64.381674 | M19: 151.92103 | N19: 311.82757
A20: -10 | B20: -10 | C20: 66 | D20: -27 | E20: 39 | F20: -80 | G20: 61.987859 | H20: 75.612768 | I20: 42.399373 | J20: 4487 | K20: 77.87811 | L20: 59.481089 | M20: 85.445889 | N20: 222.80509
A21: -20 | B21: -5 | C21: -20 | D21: 52 | E21: -57 | F21: -86 | G21: 9.5415387 | H21: 15.008914 | I21: 155.44955 | J21: 2109 | K21: 57 | L21: 142.87407 | M21: 89.050547 | N21: 288.92462
A22: 81 | B22: -85 | C22: 79 | D22: -10 | E22: -33 | F22: 39 | G22: 23.776593 | H22: 115.1569 | I22: 41.066504 | J22: 8302 | K22: 75.026662 | L22: 122.24974 | M22: 168.4399 | N22: 365.71631
... A71: 22 | B71: 41 | C71: -39 | D71: 45 | E71: 48 | F71: 97 | G71: 34.228422 | H71: 34.618539 | I71: 111.15304 | J71: 3520 | K71: 61.131007 | L71: 101.35581 | M71: 61.741396 | N71: 224.22821

Sheet pirkums
B1: XTR detaļu skaits pirkumā | C1: atlaide atbilstošajām XTR detaļām % | D1: Kopējā maksa par noteiktām detaļām
A2: Priekšējais pārslēdz. | B2: 2 | C2: 0 | D2: =B2*cenas!J2*(1-pirkums!C2) -> 50 | L2: Darblapā pirkums šūnu apgabalā D2:D28 ievadīt formulu, kas aprēķina maksu par katru pirkumu, ņemot vērā detaļu skaitu, atlaides un cenu no darblapas cena.
A3: Aizmugurējais pārslēdz. | B3: 1 | C3: 0.035 | D3: =B3*cenas!J3*(1-pirkums!C3) -> 48.25 | K3: 22 | Q3: 2 punkti
A4: Klaņi | B4: 2 | C4: 0.03 | D4: =B4*cenas!J4*(1-pirkums!C4) -> 261.9
A5: Bremzes | B5: 2 | C5: 0.025 | D5: =B5*cenas!J5*(1-pirkums!C5) -> 136.5
A6: Pārslēdzēja slēdži | B6: 2 | C6: 0.005 | D6: =B6*cenas!J6*(1-pirkums!C6) -> 139.3
A7: Bremžu rokturi | B7: 2 | C7: 0.005 | D7: =B7*cenas!J7*(1-pirkums!C7) -> 119.4
A8: Monobloks | B8: 1 | C8: 0.01 | D8: =B8*cenas!J8*(1-pirkums!C8) -> 34.65 | K8: 23 | L8: Darblapā pirkums šūnā D29 ievadīt formulu, kas aprēķina pirkuma kopsummu. | Q8: 1 punkts
A9: Kasete | B9: 1 | C9: 0.01 | D9: =B9*cenas!J9*(1-pirkums!C9) -> 52.47
A10: Ķēde | B10: 1 | C10: 0.015 | D10: =B10*cenas!J10*(1-pirkums!C10) -> 15.76
A11: Priekšējā rumba | B11: 1 | C11: 0.03 | D11: =B11*cenas!J11*(1-pirkums!C11) -> 33.95
A12: Aizmugurējā rumba | B12: 1 | C12: 0.02 | D12: =B12*cenas!J12*(1-pirkums!C12) -> 49
A13: Diski | B13: 2 | C13: 0.025 | D13: =B13*cenas!J13*(1-pirkums!C13) -> 253.5
A14: Amortizators | B14: 1 | C14: 0.02 | D14: =B14*cenas!J14*(1-pirkums!C14) -> 313.6
A15: Spieķi | B15: 60 | C15: 0.03 | D15: =B15*cenas!J15*(1-pirkums!C15) -> 3492
A16: Sēdeklis | B16: 1 | C16: 0.025 | D16: =B16*cenas!J16*(1-pirkums!C16) -> 58.5
A17: Sēdekļa stienis | B17: 1 | C17: 0.015 | D17: =B17*cenas!J17*(1-pirkums!C17) -> 23.64
A18: Rāmis | B18: 1 | C18: 0.045 | D18: =B18*cenas!J18*(1-pirkums!C18) -> 238.75
A19: Stūres stienis | B19: 1 | C19: 0.045 | D19: =B19*cenas!J19*(1-pirkums!C19) -> 13.37
A20: Stūres iznesums | B20: 1 | C20: 0.025 | D20: =B20*cenas!J20*(1-pirkums!C20) -> 39
A21: Radziņi | C21: 0.015 | D21: =B21*cenas!J21*(1-pirkums!C21) -> 0
A22: Bļodiņas | C22: 0.05 | D22: =B22*cenas!J22*(1-pirkums!C22) -> 0
A23: Trosītes | B23: 2 | C23: 0.04 | D23: =B23*cenas!J23*(1-pirkums!C23) -> 76.8
A24: Pedāļi | B24: 2 | C24: 0.01 | D24: =B24*cenas!J24*(1-pirkums!C24) -> 158.4
A25: Riepas | B25: 2 | C25: 0.035 | D25: =B25*cenas!J25*(1-pirkums!C25) -> 23.16
A26: Kameras | B26: 2 | C26: 0.01 | D26: =B26*cenas!J26*(1-pirkums!C26) -> 23.76
A27: Bremžu pastiprinātājs | C27: 0 | D27: =B27*cenas!J27*(1-pirkums!C27) -> 0
A28: Trosīšu galiņi | B28: 4 | C28: 0.02 | D28: =B28*cenas!J28*(1-pirkums!C28) -> 3.92
B29: Pirkuma kopsumma | D29: =SUM(D2:D28) -> 5659.58

Sheet cenas
B1: Cane | C1: Mavic | D1: Manitou | E1: Ritchy | F1: Selle | G1: Shimano | H1: Titec | I1: XT | J1: XTR | K1: WTB
A2: Priekšējais pārslēdz. | B2: 39.8 | C2: 28 | D2: 32.2 | E2: 33.6 | F2: 33.1 | G2: 37.1 | H2: 38.3 | I2: 40 | J2: 25 | K2: 42.5
A3: Aizmugurējais pārslēdz. | B3: 74.9 | C3: 67.3 | D3: 81.5 | E3: 71.2 | F3: 68.2 | G3: 72.4 | H3: 81.3 | I3: 79 | J3: 50 | K3: 80.2
A4: Klaņi | B4: 198.2 | C4: 190.5 | D4: 202.8 | E4: 193.7 | F4: 190.7 | G4: 194.8 | H4: 197.5 | I4: 245 | J4: 135 | K4: 207.4
A5: Bremzes | B5: 99.4 | C5: 76.2 | D5: 97.1 | E5: 86.7 | F5: 82.3 | G5: 87.4 | H5: 98.1 | I5: 90 | J5: 70 | K5: 100.6
A6: Pārslēdzēja slēdži | B6: 97.3 | C6: 81.6 | D6: 139.8 | E6: 95.6 | F6: 83.6 | G6: 99 | H6: 137.8 | I6: 159 | J6: 70 | K6: 98.4
A7: Bremžu rokturi | B7: 73.4 | C7: 60 | D7: 77 | E7: 69.6 | F7: 61.7 | G7: 71.2 | H7: 86.3 | I7: 70 | J7: 60 | K7: 73
A8: Monobloks | B8: 36.8 | C8: 35.2 | D8: 46.4 | E8: 36.1 | F8: 35.4 | G8: 43 | H8: 36 | I8: 40 | J8: 35 | K8: 38.7
A9: Kasete | B9: 64.4 | C9: 62.4 | D9: 72.3 | E9: 68.9 | F9: 62.4 | G9: 67 | H9: 63.1 | I9: 80 | J9: 53 | K9: 69.9
A10: Ķēde | B10: 25.1 | C10: 17.5 | D10: 23.3 | E10: 20.3 | F10: 20.3 | G10: 24.3 | H10: 28.9 | I10: 20 | J10: 16 | K10: 34.1
A11: Priekšējā rumba | B11: 49.2 | C11: 43 | D11: 58.5 | E11: 47.1 | F11: 46.6 | G11: 48.8 | H11: 58.5 | I11: 55 | J11: 35 | K11: 54.1
A12: Aizmugurējā rumba | B12: 99.8 | C12: 77.2 | D12: 90.9 | E12: 83.7 | F12: 79.9 | G12: 89.7 | H12: 95.7 | I12: 100 | J12: 50 | K12: 92.2
A13: Diski | B13: 83.4 | C13: 122.4 | D13: 82.4 | E13: 93.1 | F13: 90.7 | G13: 101.5 | H13: 83.3 | I13: 50 | J13: 130 | K13: 89.7
... A28: Trosīšu galiņi | B28: 3.5 | C28: 10.4 | D28: 1.2 | E28: 7 | F28: 11.2 | G28: 14.5 | H28: 1.2 | I28: 1 | J28: 1 | K28: 4.1

Sheet Sheet2

Sheet Sheet3
B1: (Multiple Items)

Sheet velo
A1: Nr | B1: Grupa | C1: Uzvārds | D1: Vārds | E1: Klubs | F1: Laiks | G1: Ātrums | K1: 24 | L1: No lapas velo datiem jaunā darblapā iegūt kopsavilkuma tabulu, kurā būtu redzams cik bija dalībnieku, kuru vārds ir Kārlis. | Q1: 1 punkts
A2: 240 | B2: mtbW | C2: Ābele | D2: Ieva | E2: Rīga | F2: 2:03:17 | G2: 17.5
A3: 219 | B3: mtb M19 | C3: Ābelīte | D3: Renārs | F3: 1:17:53 | G3: 27.7
A4: 621 | B4: T M | C4: Ābelīts | D4: Sandis | E4: VIC velokurjers | F4: 1:02:55 | G4: 33.3
A5: 714 | B5: T M | C5: Ābelīts | D5: Valdis | E5: V-sports | F5: 1:22:23 | G5: 25.4
A6: 610 | B6: T M | C6: Ābeļkalns | D6: Ilvis | F6: 1:20:49 | G6: 25.9 | K6: 25 | L6: No lapas velo datiem jaunā darblapā iegūt kopsavilkuma tabulu, kurā būtu redzams, kāds bija katras kalnu velosipēdu (mtb) grupas dalībnieku vidējais ātrums. | Q6: 2 punkti
A7: 131 | B7: T M | C7: Ābiķis | D7: Dzintars | F7: 1:32:43 | G7: 22.6
A8: 220 | B8: T M | C8: Abiņš | D8: Juris | E8: Krāsu nams | F8: 1:01:59 | G8: 33.8
A9: 419 | B9: T M | C9: Āboliņš | D9: Gatis | E9: Viesnīca Santa | F9: 1:15:42 | G9: 27.7
A10: 535 | B10: T M | C10: Āboliņš | D10: Āris | F10: 1:23:20 | G10: 25.2
A11: 226 | B11: mtb M19 | C11: Adijāns | D11: Edgars | E11: Bosch | F11: 1:23:25 | G11: 25.8
A12: 623 | B12: T M | C12: Agejevs | D12: Aleksandrs | E12: VIC velokurjers | F12: 1:03:42 | G12: 32.9 | K12: 26 | L12: No lapas velo G kolonnas datiem izveidot histogrammu, kurā būtu redzams dalībnieku skaita sadalījums pēc vidējā ātruma intervālos pa 5km/h. | Q12: 2 punkti
A13: 104 | B13: T M | C13: Aizkalns | D13: Matīss | F13: 1:40:14 | G13: 20.9
A14: 104 | B14: T W | C14: Aizkalns | D14: Olita | E14: Jelgava | F14: 1:39:45 | G14: 21
A15: 241 | B15: mtb M16 | C15: Aizkalns | D15: Mārcis | E15: Jelgava | F15: 1:16:46 | G15: 28.1
A16: 242 | B16: mtb M36 | C16: Aizkalns | D16: Normunds | E16: Jelgava | F16: 1:50:53 | G16: 19.4
A17: 968 | B17: T M | C17: Aizups | D17: Andris | F17: 1:16:55 | G17: 27.3
A18: 921 | B18: T W | C18: Akmentiņa | D18: Laura | E18: Valmieras kom.Grods | F18: 1:59:21 | G18: 17.5
A19: 106 | B19: T M | C19: Āķis | D19: Mikus | E19: Rīga | F19: 1:41:19 | G19: 20.7
A20: 106 | B20: T M | C20: Āķis | D20: Helmuts | E20: Rīga | F20: 1:39:28 | G20: 21.1
A21: 220 | B21: mtb M19 | C21: Āķis | D21: Sandis | F21: 1:15:34 | G21: 28.5
A22: 127 | B22: T M | C22: Albāts | D22: Jānis | E22: Rīga | F22: 2:04:13 | G22: 16.9
A23: 142 | B23: T M | C23: Albāts | D23: Lauris | E23: Rīga | F23: 2:04:12 | G23: 16.9
A24: 822 | B24: T W | C24: Alberte | D24: Madara | F24: 1:10:22 | G24: 29.8
A25: 289 | B25: T M | C25: Alberts | D25: Māris | F25: 1:08:40 | G25: 30.5
A26: 130 | B26: T M | C26: Aleksandrovs | D26: Aleksandrs | E26: Veloserviss | F26: 0:57:37 | G26: 36.4
A27: 107 | B27: T M | C27: Aleksīns | D27: Viesturs | E27: Rīga | F27: 1:12:16 | G27: 29
A28: 221 | B28: mtb M46 | C28: Aliks | D28: Juris | F28: 1:52:09 | G28: 19.2
A29: 216 | B29: mtb M46 | C29: Alksnis | D29: Māris | F29: 1:30:07 | G29: 23.9
A30: 592 | B30: T M | C30: Alsiņš | D30: Reinis | F30: 1:28:52 | G30: 23.6
A31: 593 | B31: T M | C31: Alsiņš | D31: Modris | F31: 1:17:36 | G31: 27
A32: 142 | B32: T M | C32: Alviķis | D32: Pauls | E32: Sigulda | F32: 1:44:53 | G32: 20
A33: 7 | B33: M46 | C33: Aļeksejevs | D33: Leonīds | F33: 1:38:56 | G33: 43.3
A34: 223 | B34: mtb M36 | C34: Ambainis | D34: Aigars | F34: 1:10:30 | G34: 30.6
A35: 105 | B35: T M | C35: Ameters | D35: Armands | E35: Rīga | F35: 1:35:46 | G35: 21.9
A36: 672 | B36: T M | C36: Anderdorfs | D36: Janeks | E36: Ventspils | F36: 1:06:33 | G36: 31.5
A37: 219 | B37: mtb M36 | C37: Andersons | D37: Arvils | F37: 1:10:32 | G37: 30.6
A38: 500 | B38: T M | C38: Andersons | D38: Ilmārs | E38: Vello 31 | F38: 1:51:44 | G38: 18.7
A39: 357 | B39: T M | C39: Andrejevs | D39: Andrejs | E39: Valka | F39: 1:06:21 | G39: 31.6
A40: 436 | B40: T W | C40: Andrijanova | D40: Indra | F40: 1:30:50 | G40: 23.1
...

Sheet pH
A1: NaOH (ml) | B1: pH | E1: Šķīdumam pievienojot nātrija hidroksīdu, izmainās tā pH līmenis. Tabulā doti dati par pielieto nātrija hidroksīda daudzumu un pH līmeni.
A2: 0 | B2: 1 | D2: 27 | E2: Attēlo šos datus izkliedes diagrammā ar pievienotu polinomiālu tendenču līkni un tās raksturlielumiem - vienādojumu un korelācijas koeficientu. | R2: 2 punkti
A3: 10 | B3: 1.17 | D3: 28 | E3: Uzraksti formulu, kas atrod lineāru sakarību (taisnes vienādojumu) starp pielieto nātrija hidroksīdu un pH līmeni. | R3: 3 punkti
A4: 25 | B4: 1.48
A5: 45 | B5: 2.28
A6: 49.5 | B6: 3.3
A7: 49.75 | B7: 3.6 | E7: {=LINEST(B2:B11,A2:A11)} -> 0.15978803 | F7: -0.91663784
A8: 50 | B8: 7 | R8: `
A9: 50.25 | B9: 10.4
A10: 55 | B10: 11.68
A11: 60 | B11: 11.96
